[2022-11-08T16:10:56.890+0000] {taskinstance.py:1165} INFO - Dependencies all met for <TaskInstance: book_list_dag.fetch_data manual__2022-11-08T16:10:55.081217+00:00 [queued]>
[2022-11-08T16:10:56.907+0000] {taskinstance.py:1165} INFO - Dependencies all met for <TaskInstance: book_list_dag.fetch_data manual__2022-11-08T16:10:55.081217+00:00 [queued]>
[2022-11-08T16:10:56.908+0000] {taskinstance.py:1362} INFO - 
--------------------------------------------------------------------------------
[2022-11-08T16:10:56.909+0000] {taskinstance.py:1363} INFO - Starting attempt 1 of 1
[2022-11-08T16:10:56.910+0000] {taskinstance.py:1364} INFO - 
--------------------------------------------------------------------------------
[2022-11-08T16:10:56.930+0000] {taskinstance.py:1383} INFO - Executing <Task(PythonOperator): fetch_data> on 2022-11-08 16:10:55.081217+00:00
[2022-11-08T16:10:56.947+0000] {standard_task_runner.py:55} INFO - Started process 391 to run task
[2022-11-08T16:10:56.958+0000] {standard_task_runner.py:82} INFO - Running: ['***', 'tasks', 'run', 'book_list_dag', 'fetch_data', 'manual__2022-11-08T16:10:55.081217+00:00', '--job-id', '30', '--raw', '--subdir', 'DAGS_FOLDER/book_lists_dag.py', '--cfg-path', '/tmp/tmpl0sow43f']
[2022-11-08T16:10:56.960+0000] {standard_task_runner.py:83} INFO - Job 30: Subtask fetch_data
[2022-11-08T16:10:57.113+0000] {task_command.py:376} INFO - Running <TaskInstance: book_list_dag.fetch_data manual__2022-11-08T16:10:55.081217+00:00 [running]> on host 786e58bb7830
[2022-11-08T16:10:57.263+0000] {taskinstance.py:1592} INFO - Exporting the following env vars:
AIRFLOW_CTX_DAG_OWNER=***
AIRFLOW_CTX_DAG_ID=book_list_dag
AIRFLOW_CTX_TASK_ID=fetch_data
AIRFLOW_CTX_EXECUTION_DATE=2022-11-08T16:10:55.081217+00:00
AIRFLOW_CTX_TRY_NUMBER=1
AIRFLOW_CTX_DAG_RUN_ID=manual__2022-11-08T16:10:55.081217+00:00
[2022-11-08T16:11:12.739+0000] {taskinstance.py:1851} ERROR - Task failed with exception
Traceback (most recent call last):
  File "/home/airflow/.local/lib/python3.7/site-packages/airflow/operators/python.py", line 175, in execute
    return_value = self.execute_callable()
  File "/home/airflow/.local/lib/python3.7/site-packages/airflow/operators/python.py", line 193, in execute_callable
    return self.python_callable(*self.op_args, **self.op_kwargs)
  File "/opt/airflow/dags/book_lists_dag.py", line 168, in fetch_data
    res_str = cr.get_list_info()
  File "/opt/airflow/dags/book_lists_dag.py", line 113, in get_list_info
    self.add_record(cur_list_res)
  File "/opt/airflow/dags/book_lists_dag.py", line 125, in add_record
    now = datetime.datetime.now()
AttributeError: type object 'datetime.datetime' has no attribute 'datetime'
[2022-11-08T16:11:12.756+0000] {taskinstance.py:1406} INFO - Marking task as FAILED. dag_id=book_list_dag, task_id=fetch_data, execution_date=20221108T161055, start_date=20221108T161056, end_date=20221108T161112
[2022-11-08T16:11:12.776+0000] {standard_task_runner.py:105} ERROR - Failed to execute job 30 for task fetch_data (type object 'datetime.datetime' has no attribute 'datetime'; 391)
[2022-11-08T16:11:12.808+0000] {local_task_job.py:164} INFO - Task exited with return code 1
[2022-11-08T16:11:12.859+0000] {local_task_job.py:273} INFO - 0 downstream tasks scheduled from follow-on schedule check
